Workbook
Name _IDR1: [1]Analysis!$G$3
Name _IDR2: [1]Analysis!$G$3
Name A_C: [1]Analysis!$G$3
Name ALT: [1]Analysis!$G$3
Name FAN: [1]Analysis!$G$3
Name P_S: [1]Analysis!$G$3
Name TEN: [1]Analysis!$G$3
Name W_P: [1]Analysis!$G$3

Sheet EN_REPORT
I1: FEAD Performance Analysis Report
B5: File No. : | I5: Version : | O5: Date : | Q5: =TODAY()
B7: Project Information
B10: Client : | L10: Project:
B11: Number of engine cylinders： | J11: =IF([2]初始输入!C12="","",[2]初始输入!C12) | L11: Engine power | R11: =IF([2]初始输入!C13="","",[2]初始输入!C13)
B12: Problem Statement :
B13: Analysis Reference :
C14: Layout Data (input)
C30: Geometry Analysis (Input）
C33: Belt Data (input)
C35: Belt name : | J35: Multi- V Belt | O35: Geometric Dimension :
C36: Belt rib Geometry type : | K36: / | O36: Belt Height : | W36: [mm]
C37: No.of Ribs/Cord Material: | K37: / | O37: Belt Flat to Pitch : | W37: [mm]
C38: Stretch and Wear Allow : | K38: % of Length | O38: Belt Pitch to Effective : | W38: [mm]
C40: Tensioner Data (input)
C42: Tensioner Type : | O42: =IF([2]Input!F17="YES","Tensioner Arm Length :","Tensioner Line Length :") | W42: [mm]
C43: =IF([2]Input!F17="YES","Pivot Point {x,y} [mm] :","Starting Point {x,y} [mm] :") | O43: =IF([2]Input!F17="YES","Tensioner Arm Angle :","Ending Point {x,y} [mm] :") | W43: =IF([2]Input!F17="YES","[deg]",ROUND([2]Input!E44,2))
C44: Belt Design Tension [N] : | K44: N ( | L44: =I44/(9.8*0.454) | M44: Ib ) | O44: =IF([2]Input!F17="YES","Spring Rate Factor :","Nominal Point {x,y} [mm] :") | W44: =IF([2]Input!F17="YES","[Nm/deg]",ROUND([2]Input!G44,2))
C46: Layout Data (input)
C48: NO. | E48: Pulley | H48: X | K48: Y | N48: Flat | Q48: Pitch | T48: Effective | W48: Pulley
H49: Coordinate | K49: Coordinate | N49: Diameter | Q49: Diameter | T49: Diameter | W49: Type
C50: =[2]Geometry!A5
C51: =[2]Geometry!A6
C52: =[2]Geometry!A7
C53: =[2]Geometry!A8
C54: =[2]Geometry!A9
C55: =[2]Geometry!A10
C56: =[2]Geometry!A11
C57: =[2]Geometry!A12
C58: =[2]Geometry!A13
C59: =[2]Geometry!A14
C62: Layout Data (Results)
C64: Min Belt | O64: Nominal Belt
C79: Jitter risk segment | J79: =[2]初始输入!B66 | O79: Jitter risk segment | V79: =[2]初始输入!I66
C80: Interference Pulley | J80: =[2]初始输入!B68 | O80: Interference Pulley | V80: =[2]初始输入!I68
C81: Tensioner pulley swing angle | J81: =IF(AND([2]初始输入!C41="Automatic",J80="TEN"),"±"&[2]抖动计算!B5,"/") | M81: deg | O81: Tensioner pulley swing angle | V81: =IF(AND([2]初始输入!C41="Automatic",V80="TEN"),"±"&[2]抖动计算!B6,"/") | Y81: deg
C82: Distance | J82: =[2]抖动计算!S11 | M82: mm | O82: Distance | V82: =[2]初始输入!I74 | Y82: mm
C84: Max Belt | O84: Stretch & wear
C94: Jitter risk segment | J94: =[2]初始输入!B77 | O94: Jitter risk segment | V94: =[2]初始输入!I77
C95: Interference Pulley | J95: =[2]初始输入!B79 | O95: Interference Pulley | V95: =[2]初始输入!I79
...
